Workbook

Sheet Performance Appraisal- Q2
A1: WITU PERFORMANCE APPRAISAL FORM
A7: Link to Staff Contract
A9: Name (Last, First, MI):
A10: Kenneth Wakabala
A11: Department/ Program: | E11: Appraisal Period:
A12: Digital Economy Program | E12: From: | G12: April; | J12: To: | K12: August
A13: Job Title: | B13: Supervisor: | E13: Discussion Date:
A14: IT Lead | B14: Joan Babirye | E14: 46253
A16: Assessment against Key Result Areas
A19: KRA 1- AI Platform Management, Data Governance & Analytics | C19: Weight | D19: KRA Rating | E19: Employee Rating | J19: Manager Rating | O19: Agreed Rating
C20: 0.3 | E20: 1 | F20: 2 | G20: 3 | H20: 4 | I20: 5 | J20: 1 | K20: 2 | L20: 3 | M20: 4 | N20: 5 | O20: 1 | P20: 2 | Q20: 3 | R20: 4 | S20: 5
A21: KPI 1: AI-Enabled Job Matching Platform | I21: X | N21: X | S21: x
A22: KPI 2: AI Innovation and Platform Enhancement | I22: X | N22: x | S22: x
A23: KPI 3: AI Security, Privacy, and Compliance | I23: X | N23: x | S23: x
A25: Employee Comments: [specific examples] | B25: KPI 1: Implemented AI-enabled Job-matching platform basing Job seeker Qualifications, skills and job roles, ensuring system stability, seamless integration of AI components for screening the jobs related to job seeker and sends them emails and still improving on the performance to enhance user experience and platform efficiency. KPI 2: Collaborated with AI specialists like Niklas inderst from Germany and Ethan from Neexa AI to refine and enhance the platform's algorithms and overall functionality, contributing technical insights from a support perspective and developed Resume builder and Chatbot AI to improve system performance, reliability, and user experience. KPI 3: Oversee and enforce data security protocols and privacy compliance across the platform, ensuring adherence to industry standards, regulatory requirements, and best practices to protect sensitive information.
A26: Manager Comments: [specific examples] | B26: Ken has excellently performed in his role as IT lead, managing IT partnerships with Tema for Tech, enhancing WITU's 3 platforms(ElevateHER360, Nsimbi Impact Platform, and the Elevate Accelerator), including auto-screening of participants and ensuring the platform is more user-friendly for the stakeholders(Participants, instructors, and admin), the voice book keeping for Nsimbi Impact and investor readiness for the accelerator. However, Ken feels the achievement of an AI-enabled platform was not fully achieved with the team for Tech partnership. He recommends for a chatbot-enabled AI to enable participants to effectively utilise the platform. However, he appreciates the progress made on the job portal, including job matchmaking and providing multiple CV templates. The Platform also requires an embedded assessment module for assessing participants' skill levels and competencies before joining the skilling program. Therefore, Ken will ensure that the platform has online assessments and a chatbot in the coming quarter.
A28: Key Result 2: Technical Support & Digital Training Support | C28: Weight | D28: KRA Rating | E28: Employee Rating | J28: Manager Rating | O28: Agreed Rating
C29: 0.3 | E29: 1 | F29: 2 | G29: 3 | H29: 4 | I29: 5 | J29: 1 | K29: 2 | L29: 3 | M29: 4 | N29: 5 | O29: 1 | P29: 2 | Q29: 3 | R29: 4 | S29: 5
A30: KPI 1: Technical Support and Incident Resolution | I30: X | M30: X | R30: X
A31: KPI 2: IT Helpdesk Management | I31: X | N31: X | R31: X
A32: KPI 3: User Training and Digital Capacity Building | H32: X | M32: X | R32: X
A34: Employee Comments: [specific examples] | B34: KPI 1: Technical Support and Incident Resolution Delivered prompt and effective technical support to staff and program participants by resolving an average of 20 support requests per month while maintaining a 55% first-contact resolution rate. Diagnosed and resolved hardware, software, network, and connectivity issues across both in-person and virtual environments, ensuring minimal disruption to daily operations and maintaining high system availability. KPI 2: IT Helpdesk Management Managed the organization's IT Helpdesk as the IT Support Lead, providing timely technical assistance both onsite and remotely using UltraViewer. Resolved a wide range of technical issues, including Windows and Microsoft Office activation, antivirus installation and updates, user login and registration problems, email configuration, and platform access challenges for staff and program participants. This proactive support significantly reduced downtime, improved service delivery, and enhanced overall user satisfaction. KPI 3: User Training and Digital Capacity Building Conducted training sessions for staff on a range of digital tools and technologies, including Microsoft Outlook, Microsoft 365, Monday.com, the organization's eLearning platform, and general IT best practices. Training also covered file management, secure data storage, laptop handling and maintenance, cybersecurity awareness, and other practices aimed at protecting organizational IT assets and improving productivity. Provided additional one-on-one coaching and continuous technical support to staff members who were less familiar with digital technologies, particularly instructors transitioning to new platforms. Special attention was given to instructors in the Mbarara office, guiding them through fundamental tasks such as using Outlook, navigating Monday.com, uploading course notes and assignments to the eLearning platform, and effectively utilizing other digital collaboration tools. These efforts significantly improved digital literacy, increased user confidence, and promoted the effective adoption of organizational technologies.
A35: Manager Comments: [specific examples] | B35: 1. Ken ensured all key stakeholders for the Platform are well capacitated to utilise the platform, for example: (All instructors were using the platform for assignments, grading, and rewarding participant certificates, while 2257 participants were accessing notes, assignments, certificates, and other resources shared by their instructors. He notes that there is a need to ensure that all instructors share their resources through the platform rather than using personal links in order to strengthen engagement on the platform. He also needs to continuously build capacity og the job placement unit to utilize the platform for job sharing iorder ot track how many participants applied for a specific job. 2. In close collaboration with the Program Officer and Comms Lead, Ken should hold a session with the accelerator start-ups and create awareness of the accelerator platform, as he has not yet rolled it out.
A37: 3. Key Result Area 3: IT infrastructure management | C37: Weight | D37: KRA Rating | E37: Employee Rating | J37: Manager Rating | O37: Agreed Rating
C38: 0.2 | E38: 1 | F38: 2 | G38: 3 | H38: 4 | I38: 5 | J38: 1 | K38: 2 | L38: 3 | M38: 4 | N38: 5 | O38: 1 | P38: 2 | Q38: 3 | R38: 4 | S38: 5
A39: KPI 1: IT Infrastructure Management | I39: X | M39: X
A40: KP1 2: Information Security and Data Protection | I40: X
A41: KPI 3: IT Policies, Procedures, and Digital Asset Management | I41: X
A43: Employee Comments: [specific examples] | B43: KPI 1: IT Infrastructure Management Successfully managed and maintained the organization's IT infrastructure by overseeing the performance, reliability, and availability of networks, servers, and end-user devices. Coordinated the procurement, setup, and configuration of computers for participants, ensuring all required software was installed and systems were ready for use. Engraved and tagged all computers and accessories for proper asset identification and accountability. Conducted routine maintenance, software updates, and hardware upgrades to improve operational efficiency, system reliability, and business continuity. KPI 2: Information Security and Data Protection Strengthened the organization's IT security by implementing access control measures and supporting compliance with data protection requirements. Created administrator and student user accounts with appropriate permission levels to prevent unauthorized software installations and access to restricted content. Implemented consent forms across platform pages that collect personal data, ensuring users provide informed consent before submitting information. Additionally, implemented Multi-Factor Authentication (MFA), requiring users to verify their email addresses before accessing the platform, thereby enhancing account security and reducing the risk of unauthorized access. KPI 3: IT Policies, Procedures, and Digital Asset Management Developed and maintained IT policies and standard operating procedures to promote consistent technology practices across the organization while aligning documentation with internal best practices. Designed and implemented a formal IT Equipment Request Form to streamline staff requests, improve approval workflows, and enhance accountability for IT resources. Furthermore, initiated the development of a digital asset tracking system to replace the existing manual asset management process, improving the accuracy, efficiency, and traceability of organizational IT assets. Recommendation: WITU should continue investing in reliable IT infrastructure, regular maintenance, cybersecurity and data protection measures. Fully implement the digital asset tracking system and strengthen IT policies, access controls and staff awareness to improve security, accountability and operational efficiency.
A44: Manager Comments: [specific examples] | B44: Ken demonstrated strong technical leadership and innovation in delivering WITU's key digital transformation objectives during the review period. He successfully led the design, development, enhancement, deployment, and maintenance of several strategic digital platforms, including the new WITU website, Nsimbi Impact Web Loan Platform, Nsimbi Impact Android Application, and the Elevate Accelerator Platform. His contributions significantly improved platform functionality, user experience, system security, operational efficiency, and overall programme delivery. In the next quarter, Ken should focus on scaling team capacity and institutionalizing knowledge around emerging AI technologies and enhanced digital infrastructure. As WITU continues to expand its digital ecosystem, there is an opportunity for him to further strengthen the technical capability of the broader team by leading structured knowledge-sharing initiatives, mentoring colleagues on AI-enabled solutions, and developing frameworks that support sustainable adoption of new technologies.
A45: 3. Key Result Area 4:Systems Development, Integration, Innovation & Digital Safeguarding | C45: Weight | D45: KRA Rating | E45: Employee Rating | J45: Manager Rating | O45: Agreed Rating
C46: 0.2 | E46: 1 | F46: 2 | G46: 3 | H46: 4 | I46: 5 | J46: 1 | K46: 2 | L46: 3 | M46: 4 | N46: 5 | O46: 1 | P46: 2 | Q46: 3 | R46: 4 | S46: 5
A47: KPI 1: Digital Platforms & Systems Development | I47: X | M47: X | S47: x
A48: KP1 2: Technology Innovation & Platform Enhancement | I48: X | N48: x | S48: x
A49: KPI 3: Continuous Improvement & Digital Inclusion | H49: X | M49: x | R49: x
A50: Employee Comments: [specific examples] | B50: KPI 1: Successfully designed, developed, enhanced and maintained key WITU digital platforms, including the new WITU website, Nsimbi Impact web loan platform, Nsimbi Impact Android application, and Elevate Accelerator platform. This involved improving UI/UX and responsive design, implementing new system features and workflows, integrating APIs, strengthening role-based access and security, resolving technical issues, optimizing system performance, incorporating team feedback, and deploying/hosting platforms to support WITU’s programme delivery, communication, loan management and digital service objectives. KPI 2:Kept up to date with emerging technologies through continuous learning, partner Training of Trainers workshops, and evaluation of AI tools such as Neexa AI. Applied new knowledge to improve programme platforms through live-learning integrations, automated skills assessments, mentorship benchmarking, user feedback, and other technology enhancements that improved functionality and service delivery. KPI 3: Continuously gathered feedback from users and partners to improve digital platforms and initiated inclusive technology solutions such as USSD and lightweight low-data platforms. These efforts aimed to expand access to courses, job opportunities and mentorship services for users with limited internet connectivity or basic mobile phones. Recommendation: Allocate dedicated time and resources for professional development, AI research, pilot testing, and development of low-data and USSD solutions to strengthen innovation and digital inclusion.
A51: Manager Comments: [specific examples] | B51: Ken delivered strong results across all assigned KPIs and demonstrated a high level of technical expertise, innovation, and commitment to WITU's digital transformation agenda. His contributions significantly strengthened the organization's digital platforms, enhanced service delivery, and improved accessibility for beneficiaries and stakeholders.

Sheet Behavioral Xteristics
A1: WITU PERFORMANCE APPRAISAL FORM
A7: Behavioral Competencies | G7: QUARTER 1 | P7: QUARTER 2 | Y7: QUARTER 3 | AH7: QUARTER 4
G9: Employee's Rating | J9: Manager's Rating | M9: Agreed Rating | P9: Employee's Rating | S9: Manager's Rating | V9: Agreed Rating | Y9: Employee's Rating | AB9: Manager's Rating | AE9: Agreed Rating | AH9: Employee's Rating | AK9: Manager's Rating | AN9: Agreed Rating
G10: Always | H10: Occasionally | I10: Never | J10: Always | K10: Occasionally | L10: Never | M10: Always | N10: Occasionally | O10: Never | P10: Always | Q10: Occasionally | R10: Never | S10: Always | T10: Occasionally | U10: Never | V10: Always | W10: Occasionally | X10: Never | Y10: Always | Z10: Occasionally | AA10: Never | AB10: Always | AC10: Occasionally | AD10: Never | AE10: Always | AF10: Occasionally | AG10: Never | AH10: Always | AI10: Occasionally | AJ10: Never | AK10: Always | AL10: Occasionally | AM10: Never | AN10: Always | AO10: Occasionally | AP10: Never
A11: 1 | B11: Understands the values of Hive and acts in accordance with them
B13: Hard work | G13: X
B14: Confidentiality | G14: X
B15: Teamwork | G15: X
B16: Quality | G16: X
B17: Steadfastness | G17: X
B18: Creativity | G18: X
B19: Strategic Direction | G19: X
A21: 2 | B21: Acting as a team player
B23: Shares Ideas and best practices | G23: X
B24: Listens to people and understands what they are saying | G24: X
B25: Values other people's input and takes constructive criticism | G25: X
B26: Positively encourages others and builds team spirit | G26: X
B27: Achieves best results when he/she works on her own | G27: X
B28: Does not in any way build team spirit | I28: X
A30: 3 | B30: Conflict management, resolution and integrity
B32: Remains objective in the face of conflict | G32: X
B33: Works to achieve win-win situations in the face of conflict | G33: X
B34: Able to differentiate confrontation from honesty | G34: X
B35: Confrontational in the face of conflict | H35: X
B36: Accepts responsibility for mistakes | G36: X
B37: Open and honest about work situations | G37: X
A39: 4 | B39: Relationship Building
B41: Respects other WITU staff | G41: X
B42: Respects WITU's clients | G42: X
B43: Is at least non judgemental of the views of WITU's clients | H43: X
B44: Offers constructive criticism when necessary | H44: X
A46: 5 | B46: Being Creative and uses own initiative
B48: Leads/ shows by example | G48: X
B49: Constantly strives for better ways of doing things | G49: X
B50: Freely shares ideas for new ways of doing things | G50: X
A54: Manager Overall Comments: | P54: Manager Overall Comments: | Y54: Manager Overall Comments: | AH54: Manager Overall Comments:
A57: Employee Overall Comments: | P57: Employee Overall Comments: | Y57: Employee Overall Comments: | AH57: Employee Overall Comments:

Sheet OVER ALL SUMMARY
A1: WITU PERFORMANCE APPRAISAL FORM
A7: Overall Performance Summary and Rating
B9: Calculating final performance rating
B10: KRA | E10: Rating | F10: Weight (%) | G10: Weighted Rating
A11: KRA 1 | E11: ='Performance Appraisal- Q1'!C20+' Performance Appraisal- Q2'!C20+'Performance Appraisal- Q3'!C20+'Performance Appraisal- Q4'!C20 -> 0 | G11: =E11*F11 -> 0
A12: KRA 2 | E12: ='Performance Appraisal- Q1'!C30+' Performance Appraisal- Q2'!C30+'Performance Appraisal- Q3'!C30+'Performance Appraisal- Q4'!C30 -> 0 | G12: =E12*F12 -> 0
A13: KRA 3 | E13: ='Performance Appraisal- Q1'!C41+' Performance Appraisal- Q2'!C41+'Performance Appraisal- Q3'!C41+'Performance Appraisal- Q4'!C41 -> 0 | G13: =E13*F13 -> 0
A14: KRA 4 | E14: ='Performance Appraisal- Q1'!C49+' Performance Appraisal- Q2'!C49+'Performance Appraisal- Q3'!C49+'Performance Appraisal- Q4'!C49 -> 0 | G14: =E14*F14 -> 0
A15: KRA 5 | E15: ='Performance Appraisal- Q1'!C57+' Performance Appraisal- Q2'!C57+'Performance Appraisal- Q3'!C57+'Performance Appraisal- Q4'!C57 -> 0 | G15: =E15*F15 -> 0
A16: KRA 6 | E16: ='Performance Appraisal- Q1'!C65+' Performance Appraisal- Q2'!C65+'Performance Appraisal- Q3'!C65+'Performance Appraisal- Q4'!C65 -> 0 | G16: =E16*F16 -> 0
A17: KRA 7 | E17: ='Performance Appraisal- Q1'!C73+' Performance Appraisal- Q2'!C73+'Performance Appraisal- Q3'!C73+'Performance Appraisal- Q4'!C73 -> 0 | G17: =E17*F17 -> 0
A18: KRA 8 | E18: ='Performance Appraisal- Q1'!C81+' Performance Appraisal- Q2'!C81+'Performance Appraisal- Q3'!C81+'Performance Appraisal- Q4'!C81 -> 0 | G18: =E18*F18 -> 0
A19: KRA 9 | E19: ='Performance Appraisal- Q1'!C89+' Performance Appraisal- Q2'!C89+'Performance Appraisal- Q3'!C89+'Performance Appraisal- Q4'!C89 -> 0 | G19: =E19*F19 -> 0
A20: KRA 10 | E20: ='Performance Appraisal- Q1'!C97+' Performance Appraisal- Q2'!C97+'Performance Appraisal- Q3'!C97+'Performance Appraisal- Q4'!C97 -> 0 | G20: =E20*F20 -> 0
B21: TOTAL | F21: 1 | G21: =SUM(G11:G21) -> 0
A24: Manager Overall Comments:
A26: Employee Overall Comments:
A28: Overall Performance Rating: (To be completed by Manager)
A29: Outstanding | B29: Exceeds Expectations | C29: Meets Expectations | D29: Partly Met Expectations | E29: Unacceptable
A35: Employee Signature * | D35: Date Signed:
A36: Manager Signature | D36: Date Signed:
A37: HR Signature | D37: Date Signed:
A38: Director Signature | D38: Date Signed:
A40: (* Signature acknowledges that a discussion of this document has taken place, but does not indicate that I necessarily agree with the appraisal.)

Sheet Performance Appraisal- Q1
A1: WITU PERFORMANCE APPRAISAL FORM
A9: Name (Last, First, MI):
A11: Department/ Program: | E11: Appraisal Period:
E12: From: | J12: To:
A13: Job Title: | B13: Supervisor | E13: Discussion Date:
A16: Assessment against Key Result Areas
A19: KRA 1- Write it here | C19: Weight | D19: KRA Rating | E19: Employee Rating | J19: Manager Rating | O19: Agreed Rating
E20: 1 | F20: 2 | G20: 3 | H20: 4 | I20: 5 | J20: 1 | K20: 2 | L20: 3 | M20: 4 | N20: 5 | O20: 1 | P20: 2 | Q20: 3 | R20: 4 | S20: 5
A21: KPI 1:
A22: KPI 2:
A23: KPI 3:
A24: KP1 4:
A25: KPI 5:
A26: Employee Comments: [specific examples]
A27: Manager Comments: [specific examples]
A29: Key Result 2: | C29: Weight | D29: KRA Rating | E29: Employee Rating | J29: Manager Rating | O29: Agreed Rating
E30: 1 | F30: 2 | G30: 3 | H30: 4 | I30: 5 | J30: 1 | K30: 2 | L30: 3 | M30: 4 | N30: 5 | O30: 1 | P30: 2 | Q30: 3 | R30: 4 | S30: 5
A31: KPI 1:
A32: KPI 2:
A33: KPI 3:
A34: KPI 4:
A35: KPI 5:
A36: KPI 6:
A37: Employee Comments: [specific examples]
A38: Manager Comments: [specific examples]
A40: 3. Key Result Area 3: | C40: Weight | D40: KRA Rating | E40: Employee Rating | J40: Manager Rating | O40: Agreed Rating
E41: 1 | F41: 2 | G41: 3 | H41: 4 | I41: 5 | J41: 1 | K41: 2 | L41: 3 | M41: 4 | N41: 5 | O41: 1 | P41: 2 | Q41: 3 | R41: 4 | S41: 5
A42: KPI 1:
A43: KPI 2:
A44: KPI 3:
A45: Employee Comments: [specific examples]
A46: Manager Comments: [specific examples]
A48: Key Result 4: | C48: Weight | D48: KRA Rating | E48: Employee Rating | J48: Manager Rating | O48: Agreed Rating
E49: 1 | F49: 2 | G49: 3 | H49: 4 | I49: 5 | J49: 1 | K49: 2 | L49: 3 | M49: 4 | N49: 5 | O49: 1 | P49: 2 | Q49: 3 | R49: 4 | S49: 5
A50: KPI 1:
A51: KPI 2:
A52: KPI 3
A53: Employee Comments: [specific examples]
A54: Manager Comments: [specific examples]
A56: Key Result Area 5: | C56: Weight | D56: KRA Rating | E56: Employee Rating | J56: Manager Rating | O56: Agreed Rating
...

Sheet OKR Scorecard Q1 2025.
A1: WITU OKR Scorecard Q1 2025 | R1: Week 9 (17-20 April)
A2: Name:
A3: Line manager:
A4: Dept:
F5: Week 1 (20-24 Feb) | H5: Week 2 (27 Feb-3 March) | J5: Week 3 (6-10 March) | L5: Week 4 (13-17 March) | N5: Week 5 (20-24 March) | P5: Week 6 (27-31 March) | R5: Week 7 | T5: Week 8 | V5: Week 9 | X5: Week 10 | Z5: Week 11 | AB5: Week 12 | AE5: --To be completed at end of quarter--
B6: Objective | C6: Activities | D6: Key Result | E6: Weighting | F6: Actual (Target) | G6: Comments | H6: Actual (Target) | I6: Comments | J6: Actual (Target) | K6: Comments | L6: Actual (Target) | M6: Comments | N6: Actual (Target) | O6: Comments | P6: Actual (Target) | Q6: Comments | R6: Actual (Target) | S6: Comments | T6: Actual (Target) | U6: Comments | V6: Acual (Target) | W6: Comments | X6: Acual (Target) | Y6: Comments | Z6: Acual (Target) | AA6: Comments | AB6: Acual (Target) | AC6: Comments | AE6: OKR % | AF6: Manager comments | AG6: Individual comments
B7: Strategy Development, Innovation and Implementation | E7: 20
B11: Develop, direct and manage program plan and schedule. | E11: 30
B19: Staff Development and Management | E19: 10
B23: Fundraising & Financial Managment | E23: 30
B31: Risk and Quality Assurance | E31: 10
C37: Weighting sumcheck: | E37: =SUM(E7:E35) -> 100
A38: Other Core Job Responsibilities:
C47: "What should we prioritize over all else"
C48: "Where do I need to go"
C49: "How do I know I'm getting there"
C50: “What will I do to get there”

Sheet OKR Scorecard Q2 2025
A1: WITU OKR Scorecard Q2 2025
A3: Name:
A4: Line manager:
A5: Dept:
F6: Week 1 (3-7 April) | H6: Week 2 (10-14 April) | J6: Week 3 (17-21 April) | L6: Week 4 (24-28 April) | N6: Week 5 (2-5 May) | P6: Week 6 (8-12 May) | R6: Week 7 (15-19 May) | T6: Week 8 (22-26 May) | V6: Week 9(29 May-2 June) | X6: Week 10 (5-8 June) | Z6: Week 11 (12-16 June) | AB6: Week 12 (19-23 June) | AD6: Week 12 (26-30 June) | AF6: --To be completed at end of quarter--
B7: Objective | C7: Activities | D7: Key Result | E7: Weighting | F7: Actual (Target) | G7: Comments | H7: Actual (Target) | I7: Comments | J7: Actual (Target) | K7: Comments | L7: Actual (Target) | M7: Comments | N7: Actual (Target) | O7: Comments | P7: Actual (Target) | Q7: Comments | R7: Actual (Target) | S7: Comments | T7: Actual (Target) | U7: Comments | V7: Actual (Target) | W7: Comments | X7: Actual (Target) | Y7: Comments | Z7: Actual (Target) | AA7: Comments | AB7: Actual (Target) | AC7: Comments | AD7: Actual (Target) | AE7: Comments | AF7: OKR % | AG7: Manager comments | AH7: Individual comments
B8: Strategy Development, Innovation and Implementation | E8: 20
B12: Develop, direct and manage program plan and schedule. | E12: 30
B20: Staff Development and Management | E20: 10
B24: Fundraising & Financial Managment | E24: 30
B32: Risk and Quality Assurance | E32: 10
C38: Weighting sumcheck: | E38: =SUM(E8:E36) -> 100
A39: Other Core Job Responsibilities:
C48: "What should we prioritize over all else"
C49: "Where do I need to go"
C50: "How do I know I'm getting there"
C51: “What will I do to get there”

Sheet  Performance Appraisal- Q2
A1: WITU PERFORMANCE APPRAISAL FORM
A9: Name (Last, First, MI):
A11: Department/ Program: | E11: Appraisal Period:
E12: From: | J12: To:
A13: Job Title: | B13: Supervisor | E13: Discussion Date:
A16: Assessment against Key Result Areas
A19: KRA 1- Write it here | C19: Weight | D19: KRA Rating | E19: Employee Rating | J19: Manager Rating | O19: Agreed Rating
E20: 1 | F20: 2 | G20: 3 | H20: 4 | I20: 5 | J20: 1 | K20: 2 | L20: 3 | M20: 4 | N20: 5 | O20: 1 | P20: 2 | Q20: 3 | R20: 4 | S20: 5
A21: KPI 1:
A22: KPI 2:
A23: KPI 3:
A24: KP1 4:
A25: KPI 5:
A26: Employee Comments: [specific examples]
A27: Manager Comments: [specific examples]
A29: Key Result 2: | C29: Weight | D29: KRA Rating | E29: Employee Rating | J29: Manager Rating | O29: Agreed Rating
E30: 1 | F30: 2 | G30: 3 | H30: 4 | I30: 5 | J30: 1 | K30: 2 | L30: 3 | M30: 4 | N30: 5 | O30: 1 | P30: 2 | Q30: 3 | R30: 4 | S30: 5
A31: KPI 1:
A32: KPI 2:
A33: KPI 3:
A34: KPI 4:
A35: KPI 5:
A36: KPI 6:
A37: Employee Comments: [specific examples]
A38: Manager Comments: [specific examples]
A40: 3. Key Result Area 3: | C40: Weight | D40: KRA Rating | E40: Employee Rating | J40: Manager Rating | O40: Agreed Rating
E41: 1 | F41: 2 | G41: 3 | H41: 4 | I41: 5 | J41: 1 | K41: 2 | L41: 3 | M41: 4 | N41: 5 | O41: 1 | P41: 2 | Q41: 3 | R41: 4 | S41: 5
A42: KPI 1:
A43: KPI 2:
A44: KPI 3:
A45: Employee Comments: [specific examples]
A46: Manager Comments: [specific examples]
A48: Key Result 4: | C48: Weight | D48: KRA Rating | E48: Employee Rating | J48: Manager Rating | O48: Agreed Rating
E49: 1 | F49: 2 | G49: 3 | H49: 4 | I49: 5 | J49: 1 | K49: 2 | L49: 3 | M49: 4 | N49: 5 | O49: 1 | P49: 2 | Q49: 3 | R49: 4 | S49: 5
A50: KPI 1:
A51: KPI 2:
A52: KPI 3
A53: Employee Comments: [specific examples]
A54: Manager Comments: [specific examples]
A56: Key Result Area 5: | C56: Weight | D56: KRA Rating | E56: Employee Rating | J56: Manager Rating | O56: Agreed Rating
...

Sheet OKR Scorecard Q3 2025.
A1: WITU OKR Scorecard Q3 2025 | R1: Week 9 (17-20 April)
A2: Name:
A3: Line manager:
A4: Dept:
F5: Week 1 (3-7 July) | H5: Week 2 (10-14 July) | J5: Week 3 (17-21 July) | L5: Week 4 (24-28 July) | N5: Week 5 (31 July- 4 Aug) | P5: Week 6 (7-11 Aug) | R5: Week 7 (14-18 Aug) | T5: Week 8 (21-25 Aug) | V5: Week 9 (28 Aug-1 Sept) | X5: Week 10 (4-8 Sept) | Z5: Week 11 (11-15 Sept) | AB5: Week 12 (18-22 Sept) | AD5: Weeek 13 (25-29 Sept) | AF5: --To be completed at end of quarter--
B6: Objective | C6: Activities | D6: Key Result | E6: Weighting | F6: Actual (Target) | G6: Comments | H6: Actual (Target) | I6: Comments | J6: Actual (Target) | K6: Comments | L6: Actual (Target) | M6: Comments | N6: Actual (Target) | O6: Comments | P6: Actual (Target) | Q6: Comments | R6: Actual (Target) | S6: Comments | T6: Actual (Target) | U6: Comments | V6: Actual (Target) | W6: Comments | X6: Actual (Target) | Y6: Comments | Z6: Actual (Target) | AA6: Comments | AB6: Actual (Target) | AC6: Comments | AD6: Actual (Target) | AE6: Comments | AF6: OKR % | AG6: Manager comments | AH6: Individual comments
B7: Strategy Development, Innovation and Implementation | E7: 20
B14: Develop, direct and manage program plan and schedule. | E14: 30
B22: Staff Development and Management | E22: 10
B26: Fundraising & Financial Managment | E26: 30
B34: Risk and Quality Assurance | E34: 10
C40: Weighting sumcheck: | E40: =SUM(E7:E38) -> 100
A41: Other Core Job Responsibilities:
C50: "What should we prioritize over all else"
C51: "Where do I need to go"
C52: "How do I know I'm getting there"
C53: “What will I do to get there”

Sheet Performance Appraisal- Q3
A1: HIVE COLAB PERFORMANCE APPRAISAL FORM
A9: Name (Last, First, MI):
A11: Department/ Program: | E11: Appraisal Period:
E12: From: | J12: To:
A13: Job Title: | B13: Supervisor | E13: Discussion Date:
A16: Assessment against Key Result Areas
A19: KRA 1- Write it here | C19: Weight | D19: KRA Rating | E19: Employee Rating | J19: Manager Rating | O19: Agreed Rating
E20: 1 | F20: 2 | G20: 3 | H20: 4 | I20: 5 | J20: 1 | K20: 2 | L20: 3 | M20: 4 | N20: 5 | O20: 1 | P20: 2 | Q20: 3 | R20: 4 | S20: 5
A21: KPI 1:
A22: KPI 2:
A23: KPI 3:
A24: KP1 4:
A25: KPI 5:
A26: Employee Comments: [specific examples]
A27: Manager Comments: [specific examples]
A29: Key Result 2: | C29: Weight | D29: KRA Rating | E29: Employee Rating | J29: Manager Rating | O29: Agreed Rating
E30: 1 | F30: 2 | G30: 3 | H30: 4 | I30: 5 | J30: 1 | K30: 2 | L30: 3 | M30: 4 | N30: 5 | O30: 1 | P30: 2 | Q30: 3 | R30: 4 | S30: 5
A31: KPI 1:
A32: KPI 2:
A33: KPI 3:
A34: KPI 4:
A35: KPI 5:
A36: KPI 6:
A37: Employee Comments: [specific examples]
A38: Manager Comments: [specific examples]
A40: Key Result Area 4:IT Infrastructure Management | C40: Weight | D40: KRA Rating | E40: Employee Rating | J40: Manager Rating | O40: Agreed Rating
E41: 1 | F41: 2 | G41: 3 | H41: 4 | I41: 5 | J41: 1 | K41: 2 | L41: 3 | M41: 4 | N41: 5 | O41: 1 | P41: 2 | Q41: 3 | R41: 4 | S41: 5
A42: KPI 1: Lead Team Capacity Building on AI Infrastructure
A43: KPI 2: Establish an AI Innovation and Experimentation Framework
A44: KPI 3: Strengthen Knowledge Transfer and Documentation
A45: Employee Comments: [specific examples]
A46: Manager Comments: [specific examples]
A48: Key Result 4: | C48: Weight | D48: KRA Rating | E48: Employee Rating | J48: Manager Rating | O48: Agreed Rating
E49: 1 | F49: 2 | G49: 3 | H49: 4 | I49: 5 | J49: 1 | K49: 2 | L49: 3 | M49: 4 | N49: 5 | O49: 1 | P49: 2 | Q49: 3 | R49: 4 | S49: 5
A50: KPI 1:
A51: KPI 2:
A52: KPI 3
A53: Employee Comments: [specific examples]
A54: Manager Comments: [specific examples]
A56: Key Result Area 5: | C56: Weight | D56: KRA Rating | E56: Employee Rating | J56: Manager Rating | O56: Agreed Rating
...

Sheet OKR Scorecard Q4 2025 
A1: WITU OKR Scorecard Q4 2025 | R1: Week 9 (17-20 April)
A2: Name:
A3: Line manager:
A4: Dept:
F5: Week 1 (2-6 Oct) | H5: Week 2 (9-13 Oct) | J5: Week 3 (16-20 Oct) | L5: Week 4 (23-27 Oct) | N5: Week 5 (30 Oct- 3 Nov) | P5: Week 6 (6-10 Nov) | R5: Week 7 (13-17 Nov) | T5: Week 8 (20-24 Nov) | V5: Week 9 (27 Nov-1 Dec) | X5: Week 10 (4-8 Dec) | Z5: Week 11 (11-15 Dec) | AB5: Week 12 (18-22 Dec) | AD5: Weeek 13 (27-29 Dec) | AF5: --To be completed at end of quarter--
B6: Objective | C6: Activities | D6: Key Result | E6: Weighting | F6: Actual (Target) | G6: Comments | H6: Actual (Target) | I6: Comments | J6: Actual (Target) | K6: Comments | L6: Actual (Target) | M6: Comments | N6: Actual (Target) | O6: Comments | P6: Actual (Target) | Q6: Comments | R6: Actual (Target) | S6: Comments | T6: Actual (Target) | U6: Comments | V6: Actual (Target) | W6: Comments | X6: Actual (Target) | Y6: Comments | Z6: Actual (Target) | AA6: Comments | AB6: Actual (Target) | AC6: Comments | AD6: Actual (Target) | AE6: Comments | AF6: OKR % | AG6: Manager comments | AH6: Individual comments
B7: Strategy Development, Innovation and Implementation | E7: 20
B14: Develop, direct and manage program plan and schedule. | E14: 30
B22: Staff Development and Management | E22: 10
B26: Fundraising & Financial Managment | E26: 30
B34: Risk and Quality Assurance | E34: 10
C40: Weighting sumcheck: | E40: =SUM(E7:E38) -> 100
A41: Other Core Job Responsibilities:
C50: "What should we prioritize over all else"
C51: "Where do I need to go"
C52: "How do I know I'm getting there"
C53: “What will I do to get there”

Sheet Performance Appraisal- Q4
A1: WITU PERFORMANCE APPRAISAL FORM
A9: Name (Last, First, MI):
A11: Department/ Program: | E11: Appraisal Period:
E12: From: | J12: To:
A13: Job Title: | B13: Supervisor | E13: Discussion Date:
A16: Assessment against Key Result Areas
A19: KRA 1- Write it here | C19: Weight | D19: KRA Rating | E19: Employee Rating | J19: Manager Rating | O19: Agreed Rating
E20: 1 | F20: 2 | G20: 3 | H20: 4 | I20: 5 | J20: 1 | K20: 2 | L20: 3 | M20: 4 | N20: 5 | O20: 1 | P20: 2 | Q20: 3 | R20: 4 | S20: 5
A21: KPI 1:
A22: KPI 2:
A23: KPI 3:
A24: KP1 4:
A25: KPI 5:
A26: Employee Comments: [specific examples]
A27: Manager Comments: [specific examples]
A29: Key Result 2: | C29: Weight | D29: KRA Rating | E29: Employee Rating | J29: Manager Rating | O29: Agreed Rating
E30: 1 | F30: 2 | G30: 3 | H30: 4 | I30: 5 | J30: 1 | K30: 2 | L30: 3 | M30: 4 | N30: 5 | O30: 1 | P30: 2 | Q30: 3 | R30: 4 | S30: 5
A31: KPI 1:
A32: KPI 2:
A33: KPI 3:
A34: KPI 4:
A35: KPI 5:
A36: KPI 6:
A37: Employee Comments: [specific examples]
A38: Manager Comments: [specific examples]
A40: 3. Key Result Area 3: | C40: Weight | D40: KRA Rating | E40: Employee Rating | J40: Manager Rating | O40: Agreed Rating
E41: 1 | F41: 2 | G41: 3 | H41: 4 | I41: 5 | J41: 1 | K41: 2 | L41: 3 | M41: 4 | N41: 5 | O41: 1 | P41: 2 | Q41: 3 | R41: 4 | S41: 5
A42: KPI 1:
A43: KPI 2:
A44: KPI 3:
A45: Employee Comments: [specific examples]
A46: Manager Comments: [specific examples]
A48: Key Result 4: | C48: Weight | D48: KRA Rating | E48: Employee Rating | J48: Manager Rating | O48: Agreed Rating
E49: 1 | F49: 2 | G49: 3 | H49: 4 | I49: 5 | J49: 1 | K49: 2 | L49: 3 | M49: 4 | N49: 5 | O49: 1 | P49: 2 | Q49: 3 | R49: 4 | S49: 5
A50: KPI 1:
A51: KPI 2:
A52: KPI 3
A53: Employee Comments: [specific examples]
A54: Manager Comments: [specific examples]
A56: Key Result Area 5: | C56: Weight | D56: KRA Rating | E56: Employee Rating | J56: Manager Rating | O56: Agreed Rating
...
